2024-09-23 09:13:19,059 [31m[1mWARNING: This is a development server. Do not use it in a production deployment. Use a production WSGI server instead.[0m
 * Running on http://127.0.0.1:5000
2024-09-23 09:13:19,059 [33mPress CTRL+C to quit[0m
2024-09-23 09:13:19,060  * Restarting with stat
2024-09-23 09:13:19,209  * Debugger is active!
2024-09-23 09:13:19,258  * Debugger PIN: 965-499-120
2024-09-23 09:14:08,468 [31m[1mWARNING: This is a development server. Do not use it in a production deployment. Use a production WSGI server instead.[0m
 * Running on http://127.0.0.1:5000
2024-09-23 09:14:08,468 [33mPress CTRL+C to quit[0m
2024-09-23 09:14:08,469  * Restarting with stat
2024-09-23 09:14:08,627  * Debugger is active!
2024-09-23 09:14:08,628  * Debugger PIN: 965-499-120
[2024-09-24 06:34:36 +0000] [9849] [DEBUG] Current configuration:
  config: ./gunicorn.conf.py
  wsgi_app: None
  bind: ['0.0.0.0:5000']
  backlog: 2048
  workers: 3
  worker_class: sync
  threads: 1
  worker_connections: 1000
  max_requests: 0
  max_requests_jitter: 0
  timeout: 30
  graceful_timeout: 30
  keepalive: 2
  limit_request_line: 4094
  limit_request_fields: 100
  limit_request_field_size: 8190
  reload: False
  reload_engine: auto
  reload_extra_files: []
  spew: False
  check_config: False
  print_config: False
  preload_app: False
  sendfile: None
  reuse_port: False
  chdir: /home/user/fproject/sport_auth
  daemon: False
  raw_env: []
  pidfile: None
  worker_tmp_dir: None
  user: 1000
  group: 1003
  umask: 0
  initgroups: False
  tmp_upload_dir: None
  secure_scheme_headers: {'X-FORWARDED-PROTOCOL': 'ssl', 'X-FORWARDED-PROTO': 'https', 'X-FORWARDED-SSL': 'on'}
  forwarded_allow_ips: ['127.0.0.1', '::1']
  accesslog: None
  disable_redirect_access_to_syslog: False
  access_log_format: %(h)s %(l)s %(u)s %(t)s "%(r)s" %(s)s %(b)s "%(f)s" "%(a)s"
  errorlog: app.log
  loglevel: debug
  capture_output: True
  logger_class: gunicorn.glogging.Logger
  logconfig: None
  logconfig_dict: {}
  logconfig_json: None
  syslog_addr: udp://localhost:514
  syslog: False
  syslog_prefix: None
  syslog_facility: user
  enable_stdio_inheritance: False
  statsd_host: None
  dogstatsd_tags: 
  statsd_prefix: 
  proc_name: None
  default_proc_name: wsgi:app
  pythonpath: None
  paste: None
  on_starting: <function OnStarting.on_starting at 0x7fdb47565510>
  on_reload: <function OnReload.on_reload at 0x7fdb47565630>
  when_ready: <function WhenReady.when_ready at 0x7fdb47565750>
  pre_fork: <function Prefork.pre_fork at 0x7fdb47565870>
  post_fork: <function Postfork.post_fork at 0x7fdb47565990>
  post_worker_init: <function PostWorkerInit.post_worker_init at 0x7fdb47565ab0>
  worker_int: <function WorkerInt.worker_int at 0x7fdb47565bd0>
  worker_abort: <function WorkerAbort.worker_abort at 0x7fdb47565cf0>
  pre_exec: <function PreExec.pre_exec at 0x7fdb47565e10>
  pre_request: <function PreRequest.pre_request at 0x7fdb47565f30>
  post_request: <function PostRequest.post_request at 0x7fdb47565fc0>
  child_exit: <function ChildExit.child_exit at 0x7fdb475660e0>
  worker_exit: <function WorkerExit.worker_exit at 0x7fdb47566200>
  nworkers_changed: <function NumWorkersChanged.nworkers_changed at 0x7fdb47566320>
  on_exit: <function OnExit.on_exit at 0x7fdb47566440>
  ssl_context: <function NewSSLContext.ssl_context at 0x7fdb47566560>
  proxy_protocol: False
  proxy_allow_ips: ['127.0.0.1', '::1']
  keyfile: None
  certfile: None
  ssl_version: 2
  cert_reqs: 0
  ca_certs: None
  suppress_ragged_eofs: True
  do_handshake_on_connect: False
  ciphers: None
  raw_paste_global_conf: []
  permit_obsolete_folding: False
  strip_header_spaces: False
  permit_unconventional_http_method: False
  permit_unconventional_http_version: False
  casefold_http_method: False
  forwarder_headers: ['SCRIPT_NAME', 'PATH_INFO']
  header_map: drop
[2024-09-24 06:34:36 +0000] [9849] [INFO] Starting gunicorn 23.0.0
[2024-09-24 06:34:36 +0000] [9849] [DEBUG] Arbiter booted
[2024-09-24 06:34:36 +0000] [9849] [INFO] Listening at: http://0.0.0.0:5000 (9849)
[2024-09-24 06:34:36 +0000] [9849] [INFO] Using worker: sync
[2024-09-24 06:34:36 +0000] [9850] [INFO] Booting worker with pid: 9850
[2024-09-24 06:34:36 +0000] [9851] [INFO] Booting worker with pid: 9851
[2024-09-24 06:34:36 +0000] [9850] [ERROR] Exception in worker process
Traceback (most recent call last):
  File "/home/user/fproject/fprojectenv/lib/python3.10/site-packages/gunicorn/arbiter.py", line 608, in spawn_worker
    worker.init_process()
  File "/home/user/fproject/fprojectenv/lib/python3.10/site-packages/gunicorn/workers/base.py", line 135, in init_process
    self.load_wsgi()
  File "/home/user/fproject/fprojectenv/lib/python3.10/site-packages/gunicorn/workers/base.py", line 147, in load_wsgi
    self.wsgi = self.app.wsgi()
  File "/home/user/fproject/fprojectenv/lib/python3.10/site-packages/gunicorn/app/base.py", line 66, in wsgi
    self.callable = self.load()
  File "/home/user/fproject/fprojectenv/lib/python3.10/site-packages/gunicorn/app/wsgiapp.py", line 57, in load
    return self.load_wsgiapp()
  File "/home/user/fproject/fprojectenv/lib/python3.10/site-packages/gunicorn/app/wsgiapp.py", line 47, in load_wsgiapp
    return util.import_app(self.app_uri)
  File "/home/user/fproject/fprojectenv/lib/python3.10/site-packages/gunicorn/util.py", line 370, in import_app
    mod = importlib.import_module(module)
  File "/usr/lib/python3.10/importlib/__init__.py", line 126, in import_module
    return _bootstrap._gcd_import(name[level:], package, level)
  File "<frozen importlib._bootstrap>", line 1050, in _gcd_import
  File "<frozen importlib._bootstrap>", line 1027, in _find_and_load
  File "<frozen importlib._bootstrap>", line 1006, in _find_and_load_unlocked
  File "<frozen importlib._bootstrap>", line 688, in _load_unlocked
  File "<frozen importlib._bootstrap_external>", line 883, in exec_module
  File "<frozen importlib._bootstrap>", line 241, in _call_with_frames_removed
  File "/home/user/fproject/sport_auth/wsgi.py", line 1, in <module>
    from app import app
  File "/home/user/fproject/sport_auth/app.py", line 3, in <module>
    from routes import (auth_routes, post_routes, user_routes, like_routes, comment_routes, rating_routes,
  File "/home/user/fproject/sport_auth/routes/comment_routes.py", line 97
    print("count comments = %d", comment_count")
                                              ^
SyntaxError: unterminated string literal (detected at line 97)
[2024-09-24 06:34:36 +0000] [9850] [INFO] Worker exiting (pid: 9850)
[2024-09-24 06:34:36 +0000] [9852] [INFO] Booting worker with pid: 9852
[2024-09-24 06:34:36 +0000] [9849] [DEBUG] 3 workers
[2024-09-24 06:34:36 +0000] [9849] [ERROR] Worker (pid:9850) exited with code 3
[2024-09-24 06:34:36 +0000] [9851] [ERROR] Exception in worker process
Traceback (most recent call last):
  File "/home/user/fproject/fprojectenv/lib/python3.10/site-packages/gunicorn/arbiter.py", line 608, in spawn_worker
    worker.init_process()
  File "/home/user/fproject/fprojectenv/lib/python3.10/site-packages/gunicorn/workers/base.py", line 135, in init_process
    self.load_wsgi()
  File "/home/user/fproject/fprojectenv/lib/python3.10/site-packages/gunicorn/workers/base.py", line 147, in load_wsgi
    self.wsgi = self.app.wsgi()
  File "/home/user/fproject/fprojectenv/lib/python3.10/site-packages/gunicorn/app/base.py", line 66, in wsgi
    self.callable = self.load()
  File "/home/user/fproject/fprojectenv/lib/python3.10/site-packages/gunicorn/app/wsgiapp.py", line 57, in load
    return self.load_wsgiapp()
  File "/home/user/fproject/fprojectenv/lib/python3.10/site-packages/gunicorn/app/wsgiapp.py", line 47, in load_wsgiapp
    return util.import_app(self.app_uri)
  File "/home/user/fproject/fprojectenv/lib/python3.10/site-packages/gunicorn/util.py", line 370, in import_app
    mod = importlib.import_module(module)
  File "/usr/lib/python3.10/importlib/__init__.py", line 126, in import_module
    return _bootstrap._gcd_import(name[level:], package, level)
  File "<frozen importlib._bootstrap>", line 1050, in _gcd_import
  File "<frozen importlib._bootstrap>", line 1027, in _find_and_load
  File "<frozen importlib._bootstrap>", line 1006, in _find_and_load_unlocked
  File "<frozen importlib._bootstrap>", line 688, in _load_unlocked
  File "<frozen importlib._bootstrap_external>", line 883, in exec_module
  File "<frozen importlib._bootstrap>", line 241, in _call_with_frames_removed
  File "/home/user/fproject/sport_auth/wsgi.py", line 1, in <module>
    from app import app
  File "/home/user/fproject/sport_auth/app.py", line 3, in <module>
    from routes import (auth_routes, post_routes, user_routes, like_routes, comment_routes, rating_routes,
  File "/home/user/fproject/sport_auth/routes/comment_routes.py", line 97
    print("count comments = %d", comment_count")
                                              ^
SyntaxError: unterminated string literal (detected at line 97)
[2024-09-24 06:34:36 +0000] [9851] [INFO] Worker exiting (pid: 9851)
[2024-09-24 06:34:36 +0000] [9852] [ERROR] Exception in worker process
Traceback (most recent call last):
  File "/home/user/fproject/fprojectenv/lib/python3.10/site-packages/gunicorn/arbiter.py", line 608, in spawn_worker
    worker.init_process()
  File "/home/user/fproject/fprojectenv/lib/python3.10/site-packages/gunicorn/workers/base.py", line 135, in init_process
    self.load_wsgi()
  File "/home/user/fproject/fprojectenv/lib/python3.10/site-packages/gunicorn/workers/base.py", line 147, in load_wsgi
    self.wsgi = self.app.wsgi()
  File "/home/user/fproject/fprojectenv/lib/python3.10/site-packages/gunicorn/app/base.py", line 66, in wsgi
    self.callable = self.load()
  File "/home/user/fproject/fprojectenv/lib/python3.10/site-packages/gunicorn/app/wsgiapp.py", line 57, in load
    return self.load_wsgiapp()
  File "/home/user/fproject/fprojectenv/lib/python3.10/site-packages/gunicorn/app/wsgiapp.py", line 47, in load_wsgiapp
    return util.import_app(self.app_uri)
  File "/home/user/fproject/fprojectenv/lib/python3.10/site-packages/gunicorn/util.py", line 370, in import_app
    mod = importlib.import_module(module)
  File "/usr/lib/python3.10/importlib/__init__.py", line 126, in import_module
    return _bootstrap._gcd_import(name[level:], package, level)
  File "<frozen importlib._bootstrap>", line 1050, in _gcd_import
  File "<frozen importlib._bootstrap>", line 1027, in _find_and_load
  File "<frozen importlib._bootstrap>", line 1006, in _find_and_load_unlocked
  File "<frozen importlib._bootstrap>", line 688, in _load_unlocked
  File "<frozen importlib._bootstrap_external>", line 883, in exec_module
  File "<frozen importlib._bootstrap>", line 241, in _call_with_frames_removed
  File "/home/user/fproject/sport_auth/wsgi.py", line 1, in <module>
    from app import app
  File "/home/user/fproject/sport_auth/app.py", line 3, in <module>
    from routes import (auth_routes, post_routes, user_routes, like_routes, comment_routes, rating_routes,
  File "/home/user/fproject/sport_auth/routes/comment_routes.py", line 97
    print("count comments = %d", comment_count")
                                              ^
SyntaxError: unterminated string literal (detected at line 97)
[2024-09-24 06:34:36 +0000] [9852] [INFO] Worker exiting (pid: 9852)
[2024-09-24 06:34:36 +0000] [9849] [ERROR] Worker (pid:9851) exited with code 3
Traceback (most recent call last):
  File "/home/user/fproject/fprojectenv/lib/python3.10/site-packages/gunicorn/arbiter.py", line 208, in run
    self.sleep()
  File "/home/user/fproject/fprojectenv/lib/python3.10/site-packages/gunicorn/arbiter.py", line 359, in sleep
    ready = select.select([self.PIPE[0]], [], [], 1.0)
  File "/home/user/fproject/fprojectenv/lib/python3.10/site-packages/gunicorn/arbiter.py", line 241, in handle_chld
    self.reap_workers()
  File "/home/user/fproject/fprojectenv/lib/python3.10/site-packages/gunicorn/arbiter.py", line 529, in reap_workers
    raise HaltServer(reason, self.WORKER_BOOT_ERROR)
gunicorn.errors.HaltServer: <HaltServer 'Worker failed to boot.' 3>

During handling of the above exception, another exception occurred:

Traceback (most recent call last):
  File "/home/user/fproject/fprojectenv/bin/gunicorn", line 8, in <module>
    sys.exit(run())
  File "/home/user/fproject/fprojectenv/lib/python3.10/site-packages/gunicorn/app/wsgiapp.py", line 66, in run
    WSGIApplication("%(prog)s [OPTIONS] [APP_MODULE]", prog=prog).run()
  File "/home/user/fproject/fprojectenv/lib/python3.10/site-packages/gunicorn/app/base.py", line 235, in run
    super().run()
  File "/home/user/fproject/fprojectenv/lib/python3.10/site-packages/gunicorn/app/base.py", line 71, in run
    Arbiter(self).run()
  File "/home/user/fproject/fprojectenv/lib/python3.10/site-packages/gunicorn/arbiter.py", line 228, in run
    self.halt(reason=inst.reason, exit_status=inst.exit_status)
  File "/home/user/fproject/fprojectenv/lib/python3.10/site-packages/gunicorn/arbiter.py", line 341, in halt
    self.stop()
  File "/home/user/fproject/fprojectenv/lib/python3.10/site-packages/gunicorn/arbiter.py", line 395, in stop
    time.sleep(0.1)
  File "/home/user/fproject/fprojectenv/lib/python3.10/site-packages/gunicorn/arbiter.py", line 241, in handle_chld
    self.reap_workers()
  File "/home/user/fproject/fprojectenv/lib/python3.10/site-packages/gunicorn/arbiter.py", line 529, in reap_workers
    raise HaltServer(reason, self.WORKER_BOOT_ERROR)
gunicorn.errors.HaltServer: <HaltServer 'Worker failed to boot.' 3>
2024-09-24 06:41:14,918 [31m[1mWARNING: This is a development server. Do not use it in a production deployment. Use a production WSGI server instead.[0m
 * Running on http://127.0.0.1:5000
2024-09-24 06:41:14,918 [33mPress CTRL+C to quit[0m
2024-09-24 06:43:29,154 [31m[1mWARNING: This is a development server. Do not use it in a production deployment. Use a production WSGI server instead.[0m
 * Running on http://127.0.0.1:5000
2024-09-24 06:43:29,154 [33mPress CTRL+C to quit[0m
2024-09-25 14:11:13,062 Exception on /user/4/progress [GET]
Traceback (most recent call last):
  File "/home/user/fproject/fprojectenv/lib/python3.10/site-packages/flask/app.py", line 1473, in wsgi_app
    response = self.full_dispatch_request()
  File "/home/user/fproject/fprojectenv/lib/python3.10/site-packages/flask/app.py", line 882, in full_dispatch_request
    rv = self.handle_user_exception(e)
  File "/home/user/fproject/fprojectenv/lib/python3.10/site-packages/flask_cors/extension.py", line 178, in wrapped_function
    return cors_after_request(app.make_response(f(*args, **kwargs)))
  File "/home/user/fproject/fprojectenv/lib/python3.10/site-packages/flask/app.py", line 880, in full_dispatch_request
    rv = self.dispatch_request()
  File "/home/user/fproject/fprojectenv/lib/python3.10/site-packages/flask/app.py", line 865, in dispatch_request
    return self.ensure_sync(self.view_functions[rule.endpoint])(**view_args)  # type: ignore[no-any-return]
  File "/home/user/fproject/sport_auth/routes/user_routes.py", line 89, in get_weight_progress
    target_weight, start_weight = progress[0]
TypeError: cannot unpack non-iterable int object
2024-09-25 14:13:43,678 Exception on /user/4/progress [GET]
Traceback (most recent call last):
  File "/home/user/fproject/fprojectenv/lib/python3.10/site-packages/flask/app.py", line 1473, in wsgi_app
    response = self.full_dispatch_request()
  File "/home/user/fproject/fprojectenv/lib/python3.10/site-packages/flask/app.py", line 882, in full_dispatch_request
    rv = self.handle_user_exception(e)
  File "/home/user/fproject/fprojectenv/lib/python3.10/site-packages/flask_cors/extension.py", line 178, in wrapped_function
    return cors_after_request(app.make_response(f(*args, **kwargs)))
  File "/home/user/fproject/fprojectenv/lib/python3.10/site-packages/flask/app.py", line 880, in full_dispatch_request
    rv = self.dispatch_request()
  File "/home/user/fproject/fprojectenv/lib/python3.10/site-packages/flask/app.py", line 865, in dispatch_request
    return self.ensure_sync(self.view_functions[rule.endpoint])(**view_args)  # type: ignore[no-any-return]
  File "/home/user/fproject/sport_auth/routes/user_routes.py", line 89, in get_weight_progress
    target_weight, start_weight = progress[0]
TypeError: cannot unpack non-iterable int object
2024-09-25 14:15:36,230 Exception on /user/4/progress [GET]
Traceback (most recent call last):
  File "/home/user/fproject/fprojectenv/lib/python3.10/site-packages/flask/app.py", line 1473, in wsgi_app
    response = self.full_dispatch_request()
  File "/home/user/fproject/fprojectenv/lib/python3.10/site-packages/flask/app.py", line 882, in full_dispatch_request
    rv = self.handle_user_exception(e)
  File "/home/user/fproject/fprojectenv/lib/python3.10/site-packages/flask_cors/extension.py", line 178, in wrapped_function
    return cors_after_request(app.make_response(f(*args, **kwargs)))
  File "/home/user/fproject/fprojectenv/lib/python3.10/site-packages/flask/app.py", line 880, in full_dispatch_request
    rv = self.dispatch_request()
  File "/home/user/fproject/fprojectenv/lib/python3.10/site-packages/flask/app.py", line 865, in dispatch_request
    return self.ensure_sync(self.view_functions[rule.endpoint])(**view_args)  # type: ignore[no-any-return]
  File "/home/user/fproject/sport_auth/routes/user_routes.py", line 89, in get_weight_progress
    target_weight, start_weight = progress[0]
TypeError: cannot unpack non-iterable int object
2024-09-25 14:20:41,508 Exception on /user/4/progress [GET]
Traceback (most recent call last):
  File "/home/user/fproject/fprojectenv/lib/python3.10/site-packages/flask/app.py", line 1473, in wsgi_app
    response = self.full_dispatch_request()
  File "/home/user/fproject/fprojectenv/lib/python3.10/site-packages/flask/app.py", line 882, in full_dispatch_request
    rv = self.handle_user_exception(e)
  File "/home/user/fproject/fprojectenv/lib/python3.10/site-packages/flask_cors/extension.py", line 178, in wrapped_function
    return cors_after_request(app.make_response(f(*args, **kwargs)))
  File "/home/user/fproject/fprojectenv/lib/python3.10/site-packages/flask/app.py", line 880, in full_dispatch_request
    rv = self.dispatch_request()
  File "/home/user/fproject/fprojectenv/lib/python3.10/site-packages/flask/app.py", line 865, in dispatch_request
    return self.ensure_sync(self.view_functions[rule.endpoint])(**view_args)  # type: ignore[no-any-return]
  File "/home/user/fproject/sport_auth/routes/user_routes.py", line 89, in get_weight_progress
    target_weight, start_weight = progress[0]
TypeError: cannot unpack non-iterable int object
2024-09-25 14:24:54,081 Exception on /user/4/progress [GET]
Traceback (most recent call last):
  File "/home/user/fproject/fprojectenv/lib/python3.10/site-packages/flask/app.py", line 1473, in wsgi_app
    response = self.full_dispatch_request()
  File "/home/user/fproject/fprojectenv/lib/python3.10/site-packages/flask/app.py", line 882, in full_dispatch_request
    rv = self.handle_user_exception(e)
  File "/home/user/fproject/fprojectenv/lib/python3.10/site-packages/flask_cors/extension.py", line 178, in wrapped_function
    return cors_after_request(app.make_response(f(*args, **kwargs)))
  File "/home/user/fproject/fprojectenv/lib/python3.10/site-packages/flask/app.py", line 880, in full_dispatch_request
    rv = self.dispatch_request()
  File "/home/user/fproject/fprojectenv/lib/python3.10/site-packages/flask/app.py", line 865, in dispatch_request
    return self.ensure_sync(self.view_functions[rule.endpoint])(**view_args)  # type: ignore[no-any-return]
  File "/home/user/fproject/sport_auth/routes/user_routes.py", line 89, in get_weight_progress
    target_weight, start_weight = progress[0]
TypeError: cannot unpack non-iterable int object
2024-09-25 14:28:20,327 Exception on /user/4/progress [GET]
Traceback (most recent call last):
  File "/home/user/fproject/fprojectenv/lib/python3.10/site-packages/flask/app.py", line 1473, in wsgi_app
    response = self.full_dispatch_request()
  File "/home/user/fproject/fprojectenv/lib/python3.10/site-packages/flask/app.py", line 882, in full_dispatch_request
    rv = self.handle_user_exception(e)
  File "/home/user/fproject/fprojectenv/lib/python3.10/site-packages/flask_cors/extension.py", line 178, in wrapped_function
    return cors_after_request(app.make_response(f(*args, **kwargs)))
  File "/home/user/fproject/fprojectenv/lib/python3.10/site-packages/flask/app.py", line 880, in full_dispatch_request
    rv = self.dispatch_request()
  File "/home/user/fproject/fprojectenv/lib/python3.10/site-packages/flask/app.py", line 865, in dispatch_request
    return self.ensure_sync(self.view_functions[rule.endpoint])(**view_args)  # type: ignore[no-any-return]
  File "/home/user/fproject/sport_auth/routes/user_routes.py", line 89, in get_weight_progress
    target_weight, start_weight = progress[0]
TypeError: cannot unpack non-iterable int object
2024-09-25 14:29:44,849 Exception on /user/4/progress [GET]
Traceback (most recent call last):
  File "/home/user/fproject/fprojectenv/lib/python3.10/site-packages/flask/app.py", line 1473, in wsgi_app
    response = self.full_dispatch_request()
  File "/home/user/fproject/fprojectenv/lib/python3.10/site-packages/flask/app.py", line 882, in full_dispatch_request
    rv = self.handle_user_exception(e)
  File "/home/user/fproject/fprojectenv/lib/python3.10/site-packages/flask_cors/extension.py", line 178, in wrapped_function
    return cors_after_request(app.make_response(f(*args, **kwargs)))
  File "/home/user/fproject/fprojectenv/lib/python3.10/site-packages/flask/app.py", line 880, in full_dispatch_request
    rv = self.dispatch_request()
  File "/home/user/fproject/fprojectenv/lib/python3.10/site-packages/flask/app.py", line 865, in dispatch_request
    return self.ensure_sync(self.view_functions[rule.endpoint])(**view_args)  # type: ignore[no-any-return]
  File "/home/user/fproject/sport_auth/routes/user_routes.py", line 89, in get_weight_progress
    target_weight, start_weight = progress[0]
TypeError: cannot unpack non-iterable int object
2024-10-04 07:39:56,339 Exception on /user/5/progress [GET]
Traceback (most recent call last):
  File "/home/user/fproject/fprojectenv/lib/python3.10/site-packages/flask/app.py", line 1473, in wsgi_app
    response = self.full_dispatch_request()
  File "/home/user/fproject/fprojectenv/lib/python3.10/site-packages/flask/app.py", line 882, in full_dispatch_request
    rv = self.handle_user_exception(e)
  File "/home/user/fproject/fprojectenv/lib/python3.10/site-packages/flask_cors/extension.py", line 178, in wrapped_function
    return cors_after_request(app.make_response(f(*args, **kwargs)))
  File "/home/user/fproject/fprojectenv/lib/python3.10/site-packages/flask/app.py", line 880, in full_dispatch_request
    rv = self.dispatch_request()
  File "/home/user/fproject/fprojectenv/lib/python3.10/site-packages/flask/app.py", line 865, in dispatch_request
    return self.ensure_sync(self.view_functions[rule.endpoint])(**view_args)  # type: ignore[no-any-return]
  File "/home/user/fproject/sport_auth/routes/user_routes.py", line 101, in get_weight_progress
    current_weight = execute_query("SELECT weight FROM users WHERE user_id = %s", (user_id,), fetchall=False)
  File "/home/user/fproject/sport_auth/database.py", line 11, in execute_query
    cur.execute(query, args)
psycopg2.errors.UndefinedColumn: column "user_id" does not exist
LINE 1: SELECT weight FROM users WHERE user_id = 5
                                       ^

2024-10-04 07:40:42,712 Exception on /user/5/progress [GET]
Traceback (most recent call last):
  File "/home/user/fproject/fprojectenv/lib/python3.10/site-packages/flask/app.py", line 1473, in wsgi_app
    response = self.full_dispatch_request()
  File "/home/user/fproject/fprojectenv/lib/python3.10/site-packages/flask/app.py", line 882, in full_dispatch_request
    rv = self.handle_user_exception(e)
  File "/home/user/fproject/fprojectenv/lib/python3.10/site-packages/flask_cors/extension.py", line 178, in wrapped_function
    return cors_after_request(app.make_response(f(*args, **kwargs)))
  File "/home/user/fproject/fprojectenv/lib/python3.10/site-packages/flask/app.py", line 880, in full_dispatch_request
    rv = self.dispatch_request()
  File "/home/user/fproject/fprojectenv/lib/python3.10/site-packages/flask/app.py", line 865, in dispatch_request
    return self.ensure_sync(self.view_functions[rule.endpoint])(**view_args)  # type: ignore[no-any-return]
  File "/home/user/fproject/sport_auth/routes/user_routes.py", line 101, in get_weight_progress
    current_weight = execute_query("SELECT weight FROM users WHERE user_id = %s", (user_id,), fetchall=False)
  File "/home/user/fproject/sport_auth/database.py", line 11, in execute_query
    cur.execute(query, args)
psycopg2.errors.UndefinedColumn: column "user_id" does not exist
LINE 1: SELECT weight FROM users WHERE user_id = 5
                                       ^

2024-10-04 07:41:16,121 Exception on /user/5/progress [GET]
Traceback (most recent call last):
  File "/home/user/fproject/fprojectenv/lib/python3.10/site-packages/flask/app.py", line 1473, in wsgi_app
    response = self.full_dispatch_request()
  File "/home/user/fproject/fprojectenv/lib/python3.10/site-packages/flask/app.py", line 882, in full_dispatch_request
    rv = self.handle_user_exception(e)
  File "/home/user/fproject/fprojectenv/lib/python3.10/site-packages/flask_cors/extension.py", line 178, in wrapped_function
    return cors_after_request(app.make_response(f(*args, **kwargs)))
  File "/home/user/fproject/fprojectenv/lib/python3.10/site-packages/flask/app.py", line 880, in full_dispatch_request
    rv = self.dispatch_request()
  File "/home/user/fproject/fprojectenv/lib/python3.10/site-packages/flask/app.py", line 865, in dispatch_request
    return self.ensure_sync(self.view_functions[rule.endpoint])(**view_args)  # type: ignore[no-any-return]
  File "/home/user/fproject/sport_auth/routes/user_routes.py", line 101, in get_weight_progress
    current_weight = execute_query("SELECT weight FROM users WHERE user_id = %s", (user_id,), fetchall=False)
  File "/home/user/fproject/sport_auth/database.py", line 11, in execute_query
    cur.execute(query, args)
psycopg2.errors.UndefinedColumn: column "user_id" does not exist
LINE 1: SELECT weight FROM users WHERE user_id = 5
                                       ^

2024-10-04 08:53:43,023 Exception on /user/5/progress [GET]
Traceback (most recent call last):
  File "/home/user/fproject/fprojectenv/lib/python3.10/site-packages/flask/app.py", line 1473, in wsgi_app
    response = self.full_dispatch_request()
  File "/home/user/fproject/fprojectenv/lib/python3.10/site-packages/flask/app.py", line 882, in full_dispatch_request
    rv = self.handle_user_exception(e)
  File "/home/user/fproject/fprojectenv/lib/python3.10/site-packages/flask_cors/extension.py", line 178, in wrapped_function
    return cors_after_request(app.make_response(f(*args, **kwargs)))
  File "/home/user/fproject/fprojectenv/lib/python3.10/site-packages/flask/app.py", line 880, in full_dispatch_request
    rv = self.dispatch_request()
  File "/home/user/fproject/fprojectenv/lib/python3.10/site-packages/flask/app.py", line 865, in dispatch_request
    return self.ensure_sync(self.view_functions[rule.endpoint])(**view_args)  # type: ignore[no-any-return]
  File "/home/user/fproject/sport_auth/routes/user_routes.py", line 101, in get_weight_progress
    current_weight = execute_query("SELECT weight FROM users WHERE user_id = %s", (user_id,), fetchall=False)
  File "/home/user/fproject/sport_auth/database.py", line 11, in execute_query
    cur.execute(query, args)
psycopg2.errors.UndefinedColumn: column "user_id" does not exist
LINE 1: SELECT weight FROM users WHERE user_id = 5
                                       ^

2024-10-04 08:56:56,126 Exception on /user/5/progress [GET]
Traceback (most recent call last):
  File "/home/user/fproject/fprojectenv/lib/python3.10/site-packages/flask/app.py", line 1473, in wsgi_app
    response = self.full_dispatch_request()
  File "/home/user/fproject/fprojectenv/lib/python3.10/site-packages/flask/app.py", line 882, in full_dispatch_request
    rv = self.handle_user_exception(e)
  File "/home/user/fproject/fprojectenv/lib/python3.10/site-packages/flask_cors/extension.py", line 178, in wrapped_function
    return cors_after_request(app.make_response(f(*args, **kwargs)))
  File "/home/user/fproject/fprojectenv/lib/python3.10/site-packages/flask/app.py", line 880, in full_dispatch_request
    rv = self.dispatch_request()
  File "/home/user/fproject/fprojectenv/lib/python3.10/site-packages/flask/app.py", line 865, in dispatch_request
    return self.ensure_sync(self.view_functions[rule.endpoint])(**view_args)  # type: ignore[no-any-return]
  File "/home/user/fproject/sport_auth/routes/user_routes.py", line 101, in get_weight_progress
    current_weight = execute_query("SELECT weight FROM users WHERE user_id = %s", (user_id,), fetchall=False)
  File "/home/user/fproject/sport_auth/database.py", line 11, in execute_query
    cur.execute(query, args)
psycopg2.errors.UndefinedColumn: column "user_id" does not exist
LINE 1: SELECT weight FROM users WHERE user_id = 5
                                       ^

2024-10-04 08:57:08,214 Exception on /user/5/progress [GET]
Traceback (most recent call last):
  File "/home/user/fproject/fprojectenv/lib/python3.10/site-packages/flask/app.py", line 1473, in wsgi_app
    response = self.full_dispatch_request()
  File "/home/user/fproject/fprojectenv/lib/python3.10/site-packages/flask/app.py", line 882, in full_dispatch_request
    rv = self.handle_user_exception(e)
  File "/home/user/fproject/fprojectenv/lib/python3.10/site-packages/flask_cors/extension.py", line 178, in wrapped_function
    return cors_after_request(app.make_response(f(*args, **kwargs)))
  File "/home/user/fproject/fprojectenv/lib/python3.10/site-packages/flask/app.py", line 880, in full_dispatch_request
    rv = self.dispatch_request()
  File "/home/user/fproject/fprojectenv/lib/python3.10/site-packages/flask/app.py", line 865, in dispatch_request
    return self.ensure_sync(self.view_functions[rule.endpoint])(**view_args)  # type: ignore[no-any-return]
  File "/home/user/fproject/sport_auth/routes/user_routes.py", line 101, in get_weight_progress
    current_weight = execute_query("SELECT weight FROM users WHERE user_id = %s", (user_id,), fetchall=False)
  File "/home/user/fproject/sport_auth/database.py", line 11, in execute_query
    cur.execute(query, args)
psycopg2.errors.UndefinedColumn: column "user_id" does not exist
LINE 1: SELECT weight FROM users WHERE user_id = 5
                                       ^

2024-10-04 09:00:17,351 Exception on /user/5/progress [GET]
Traceback (most recent call last):
  File "/home/user/fproject/fprojectenv/lib/python3.10/site-packages/flask/app.py", line 1473, in wsgi_app
    response = self.full_dispatch_request()
  File "/home/user/fproject/fprojectenv/lib/python3.10/site-packages/flask/app.py", line 882, in full_dispatch_request
    rv = self.handle_user_exception(e)
  File "/home/user/fproject/fprojectenv/lib/python3.10/site-packages/flask_cors/extension.py", line 178, in wrapped_function
    return cors_after_request(app.make_response(f(*args, **kwargs)))
  File "/home/user/fproject/fprojectenv/lib/python3.10/site-packages/flask/app.py", line 880, in full_dispatch_request
    rv = self.dispatch_request()
  File "/home/user/fproject/fprojectenv/lib/python3.10/site-packages/flask/app.py", line 865, in dispatch_request
    return self.ensure_sync(self.view_functions[rule.endpoint])(**view_args)  # type: ignore[no-any-return]
  File "/home/user/fproject/sport_auth/routes/user_routes.py", line 101, in get_weight_progress
    current_weight = execute_query("SELECT weight FROM users WHERE user_id = %s", (user_id,), fetchall=False)
  File "/home/user/fproject/sport_auth/database.py", line 11, in execute_query
    cur.execute(query, args)
psycopg2.errors.UndefinedColumn: column "user_id" does not exist
LINE 1: SELECT weight FROM users WHERE user_id = 5
                                       ^

2024-10-04 09:00:26,490 Exception on /user/5/progress [GET]
Traceback (most recent call last):
  File "/home/user/fproject/fprojectenv/lib/python3.10/site-packages/flask/app.py", line 1473, in wsgi_app
    response = self.full_dispatch_request()
  File "/home/user/fproject/fprojectenv/lib/python3.10/site-packages/flask/app.py", line 882, in full_dispatch_request
    rv = self.handle_user_exception(e)
  File "/home/user/fproject/fprojectenv/lib/python3.10/site-packages/flask_cors/extension.py", line 178, in wrapped_function
    return cors_after_request(app.make_response(f(*args, **kwargs)))
  File "/home/user/fproject/fprojectenv/lib/python3.10/site-packages/flask/app.py", line 880, in full_dispatch_request
    rv = self.dispatch_request()
  File "/home/user/fproject/fprojectenv/lib/python3.10/site-packages/flask/app.py", line 865, in dispatch_request
    return self.ensure_sync(self.view_functions[rule.endpoint])(**view_args)  # type: ignore[no-any-return]
  File "/home/user/fproject/sport_auth/routes/user_routes.py", line 101, in get_weight_progress
    current_weight = execute_query("SELECT weight FROM users WHERE user_id = %s", (user_id,), fetchall=False)
  File "/home/user/fproject/sport_auth/database.py", line 11, in execute_query
    cur.execute(query, args)
psycopg2.errors.UndefinedColumn: column "user_id" does not exist
LINE 1: SELECT weight FROM users WHERE user_id = 5
                                       ^

2024-10-04 09:01:29,567 Exception on /user/5/progress [GET]
Traceback (most recent call last):
  File "/home/user/fproject/fprojectenv/lib/python3.10/site-packages/flask/app.py", line 1473, in wsgi_app
    response = self.full_dispatch_request()
  File "/home/user/fproject/fprojectenv/lib/python3.10/site-packages/flask/app.py", line 882, in full_dispatch_request
    rv = self.handle_user_exception(e)
  File "/home/user/fproject/fprojectenv/lib/python3.10/site-packages/flask_cors/extension.py", line 178, in wrapped_function
    return cors_after_request(app.make_response(f(*args, **kwargs)))
  File "/home/user/fproject/fprojectenv/lib/python3.10/site-packages/flask/app.py", line 880, in full_dispatch_request
    rv = self.dispatch_request()
  File "/home/user/fproject/fprojectenv/lib/python3.10/site-packages/flask/app.py", line 865, in dispatch_request
    return self.ensure_sync(self.view_functions[rule.endpoint])(**view_args)  # type: ignore[no-any-return]
  File "/home/user/fproject/sport_auth/routes/user_routes.py", line 101, in get_weight_progress
    current_weight = execute_query("SELECT weight FROM users WHERE user_id = %s", (user_id,), fetchall=False)
  File "/home/user/fproject/sport_auth/database.py", line 11, in execute_query
    cur.execute(query, args)
psycopg2.errors.UndefinedColumn: column "user_id" does not exist
LINE 1: SELECT weight FROM users WHERE user_id = 5
                                       ^

2024-10-04 09:01:39,141 Exception on /user/5/progress [GET]
Traceback (most recent call last):
  File "/home/user/fproject/fprojectenv/lib/python3.10/site-packages/flask/app.py", line 1473, in wsgi_app
    response = self.full_dispatch_request()
  File "/home/user/fproject/fprojectenv/lib/python3.10/site-packages/flask/app.py", line 882, in full_dispatch_request
    rv = self.handle_user_exception(e)
  File "/home/user/fproject/fprojectenv/lib/python3.10/site-packages/flask_cors/extension.py", line 178, in wrapped_function
    return cors_after_request(app.make_response(f(*args, **kwargs)))
  File "/home/user/fproject/fprojectenv/lib/python3.10/site-packages/flask/app.py", line 880, in full_dispatch_request
    rv = self.dispatch_request()
  File "/home/user/fproject/fprojectenv/lib/python3.10/site-packages/flask/app.py", line 865, in dispatch_request
    return self.ensure_sync(self.view_functions[rule.endpoint])(**view_args)  # type: ignore[no-any-return]
  File "/home/user/fproject/sport_auth/routes/user_routes.py", line 101, in get_weight_progress
    current_weight = execute_query("SELECT weight FROM users WHERE user_id = %s", (user_id,), fetchall=False)
  File "/home/user/fproject/sport_auth/database.py", line 11, in execute_query
    cur.execute(query, args)
psycopg2.errors.UndefinedColumn: column "user_id" does not exist
LINE 1: SELECT weight FROM users WHERE user_id = 5
                                       ^

2024-10-04 09:01:54,343 Exception on /user/6/progress [GET]
Traceback (most recent call last):
  File "/home/user/fproject/fprojectenv/lib/python3.10/site-packages/flask/app.py", line 1473, in wsgi_app
    response = self.full_dispatch_request()
  File "/home/user/fproject/fprojectenv/lib/python3.10/site-packages/flask/app.py", line 882, in full_dispatch_request
    rv = self.handle_user_exception(e)
  File "/home/user/fproject/fprojectenv/lib/python3.10/site-packages/flask_cors/extension.py", line 178, in wrapped_function
    return cors_after_request(app.make_response(f(*args, **kwargs)))
  File "/home/user/fproject/fprojectenv/lib/python3.10/site-packages/flask/app.py", line 880, in full_dispatch_request
    rv = self.dispatch_request()
  File "/home/user/fproject/fprojectenv/lib/python3.10/site-packages/flask/app.py", line 865, in dispatch_request
    return self.ensure_sync(self.view_functions[rule.endpoint])(**view_args)  # type: ignore[no-any-return]
  File "/home/user/fproject/sport_auth/routes/user_routes.py", line 101, in get_weight_progress
    current_weight = execute_query("SELECT weight FROM users WHERE user_id = %s", (user_id,), fetchall=False)
  File "/home/user/fproject/sport_auth/database.py", line 11, in execute_query
    cur.execute(query, args)
psycopg2.errors.UndefinedColumn: column "user_id" does not exist
LINE 1: SELECT weight FROM users WHERE user_id = 6
                                       ^

2024-10-04 09:02:06,333 Exception on /user/6/progress [GET]
Traceback (most recent call last):
  File "/home/user/fproject/fprojectenv/lib/python3.10/site-packages/flask/app.py", line 1473, in wsgi_app
    response = self.full_dispatch_request()
  File "/home/user/fproject/fprojectenv/lib/python3.10/site-packages/flask/app.py", line 882, in full_dispatch_request
    rv = self.handle_user_exception(e)
  File "/home/user/fproject/fprojectenv/lib/python3.10/site-packages/flask_cors/extension.py", line 178, in wrapped_function
    return cors_after_request(app.make_response(f(*args, **kwargs)))
  File "/home/user/fproject/fprojectenv/lib/python3.10/site-packages/flask/app.py", line 880, in full_dispatch_request
    rv = self.dispatch_request()
  File "/home/user/fproject/fprojectenv/lib/python3.10/site-packages/flask/app.py", line 865, in dispatch_request
    return self.ensure_sync(self.view_functions[rule.endpoint])(**view_args)  # type: ignore[no-any-return]
  File "/home/user/fproject/sport_auth/routes/user_routes.py", line 101, in get_weight_progress
    current_weight = execute_query("SELECT weight FROM users WHERE user_id = %s", (user_id,), fetchall=False)
  File "/home/user/fproject/sport_auth/database.py", line 11, in execute_query
    cur.execute(query, args)
psycopg2.errors.UndefinedColumn: column "user_id" does not exist
LINE 1: SELECT weight FROM users WHERE user_id = 6
                                       ^

2024-10-04 09:02:15,163 Exception on /user/6/progress [GET]
Traceback (most recent call last):
  File "/home/user/fproject/fprojectenv/lib/python3.10/site-packages/flask/app.py", line 1473, in wsgi_app
    response = self.full_dispatch_request()
  File "/home/user/fproject/fprojectenv/lib/python3.10/site-packages/flask/app.py", line 882, in full_dispatch_request
    rv = self.handle_user_exception(e)
  File "/home/user/fproject/fprojectenv/lib/python3.10/site-packages/flask_cors/extension.py", line 178, in wrapped_function
    return cors_after_request(app.make_response(f(*args, **kwargs)))
  File "/home/user/fproject/fprojectenv/lib/python3.10/site-packages/flask/app.py", line 880, in full_dispatch_request
    rv = self.dispatch_request()
  File "/home/user/fproject/fprojectenv/lib/python3.10/site-packages/flask/app.py", line 865, in dispatch_request
    return self.ensure_sync(self.view_functions[rule.endpoint])(**view_args)  # type: ignore[no-any-return]
  File "/home/user/fproject/sport_auth/routes/user_routes.py", line 101, in get_weight_progress
    current_weight = execute_query("SELECT weight FROM users WHERE user_id = %s", (user_id,), fetchall=False)
  File "/home/user/fproject/sport_auth/database.py", line 11, in execute_query
    cur.execute(query, args)
psycopg2.errors.UndefinedColumn: column "user_id" does not exist
LINE 1: SELECT weight FROM users WHERE user_id = 6
                                       ^

2024-10-04 09:58:23,944 Exception on /user/6/progress [GET]
Traceback (most recent call last):
  File "/home/user/fproject/fprojectenv/lib/python3.10/site-packages/flask/app.py", line 1473, in wsgi_app
    response = self.full_dispatch_request()
  File "/home/user/fproject/fprojectenv/lib/python3.10/site-packages/flask/app.py", line 882, in full_dispatch_request
    rv = self.handle_user_exception(e)
  File "/home/user/fproject/fprojectenv/lib/python3.10/site-packages/flask_cors/extension.py", line 178, in wrapped_function
    return cors_after_request(app.make_response(f(*args, **kwargs)))
  File "/home/user/fproject/fprojectenv/lib/python3.10/site-packages/flask/app.py", line 880, in full_dispatch_request
    rv = self.dispatch_request()
  File "/home/user/fproject/fprojectenv/lib/python3.10/site-packages/flask/app.py", line 865, in dispatch_request
    return self.ensure_sync(self.view_functions[rule.endpoint])(**view_args)  # type: ignore[no-any-return]
  File "/home/user/fproject/sport_auth/routes/user_routes.py", line 99, in get_weight_progress
    start_weight = progress[1]
IndexError: list index out of range
2024-10-04 09:58:47,016 Exception on /user/5/progress [GET]
Traceback (most recent call last):
  File "/home/user/fproject/fprojectenv/lib/python3.10/site-packages/flask/app.py", line 1473, in wsgi_app
    response = self.full_dispatch_request()
  File "/home/user/fproject/fprojectenv/lib/python3.10/site-packages/flask/app.py", line 882, in full_dispatch_request
    rv = self.handle_user_exception(e)
  File "/home/user/fproject/fprojectenv/lib/python3.10/site-packages/flask_cors/extension.py", line 178, in wrapped_function
    return cors_after_request(app.make_response(f(*args, **kwargs)))
  File "/home/user/fproject/fprojectenv/lib/python3.10/site-packages/flask/app.py", line 880, in full_dispatch_request
    rv = self.dispatch_request()
  File "/home/user/fproject/fprojectenv/lib/python3.10/site-packages/flask/app.py", line 865, in dispatch_request
    return self.ensure_sync(self.view_functions[rule.endpoint])(**view_args)  # type: ignore[no-any-return]
  File "/home/user/fproject/sport_auth/routes/user_routes.py", line 99, in get_weight_progress
    start_weight = progress[1]
IndexError: list index out of range
2024-10-04 10:02:29,793 Exception on /user/5/progress [GET]
Traceback (most recent call last):
  File "/home/user/fproject/fprojectenv/lib/python3.10/site-packages/flask/app.py", line 1473, in wsgi_app
    response = self.full_dispatch_request()
  File "/home/user/fproject/fprojectenv/lib/python3.10/site-packages/flask/app.py", line 882, in full_dispatch_request
    rv = self.handle_user_exception(e)
  File "/home/user/fproject/fprojectenv/lib/python3.10/site-packages/flask_cors/extension.py", line 178, in wrapped_function
    return cors_after_request(app.make_response(f(*args, **kwargs)))
  File "/home/user/fproject/fprojectenv/lib/python3.10/site-packages/flask/app.py", line 880, in full_dispatch_request
    rv = self.dispatch_request()
  File "/home/user/fproject/fprojectenv/lib/python3.10/site-packages/flask/app.py", line 865, in dispatch_request
    return self.ensure_sync(self.view_functions[rule.endpoint])(**view_args)  # type: ignore[no-any-return]
  File "/home/user/fproject/sport_auth/routes/user_routes.py", line 101, in get_weight_progress
    current_weight = execute_query("SELECT weight FROM users WHERE user_id = %s", (user_id,), fetchall=False)
  File "/home/user/fproject/sport_auth/database.py", line 11, in execute_query
    cur.execute(query, args)
psycopg2.errors.UndefinedColumn: column "user_id" does not exist
LINE 1: SELECT weight FROM users WHERE user_id = 5
                                       ^

2024-10-04 11:04:54,246 Exception on /user/3/progress [GET]
Traceback (most recent call last):
  File "/home/user/fproject/fprojectenv/lib/python3.10/site-packages/flask/app.py", line 1473, in wsgi_app
    response = self.full_dispatch_request()
  File "/home/user/fproject/fprojectenv/lib/python3.10/site-packages/flask/app.py", line 882, in full_dispatch_request
    rv = self.handle_user_exception(e)
  File "/home/user/fproject/fprojectenv/lib/python3.10/site-packages/flask_cors/extension.py", line 178, in wrapped_function
    return cors_after_request(app.make_response(f(*args, **kwargs)))
  File "/home/user/fproject/fprojectenv/lib/python3.10/site-packages/flask/app.py", line 880, in full_dispatch_request
    rv = self.dispatch_request()
  File "/home/user/fproject/fprojectenv/lib/python3.10/site-packages/flask/app.py", line 865, in dispatch_request
    return self.ensure_sync(self.view_functions[rule.endpoint])(**view_args)  # type: ignore[no-any-return]
  File "/home/user/fproject/sport_auth/routes/user_routes.py", line 109, in get_weight_progress
    progress = 100 - (cur_weight_difference / start_weight_difference) * 100
ZeroDivisionError: division by zero
2024-10-04 11:05:31,670 Exception on /user/3/progress [GET]
Traceback (most recent call last):
  File "/home/user/fproject/fprojectenv/lib/python3.10/site-packages/flask/app.py", line 1473, in wsgi_app
    response = self.full_dispatch_request()
  File "/home/user/fproject/fprojectenv/lib/python3.10/site-packages/flask/app.py", line 882, in full_dispatch_request
    rv = self.handle_user_exception(e)
  File "/home/user/fproject/fprojectenv/lib/python3.10/site-packages/flask_cors/extension.py", line 178, in wrapped_function
    return cors_after_request(app.make_response(f(*args, **kwargs)))
  File "/home/user/fproject/fprojectenv/lib/python3.10/site-packages/flask/app.py", line 880, in full_dispatch_request
    rv = self.dispatch_request()
  File "/home/user/fproject/fprojectenv/lib/python3.10/site-packages/flask/app.py", line 865, in dispatch_request
    return self.ensure_sync(self.view_functions[rule.endpoint])(**view_args)  # type: ignore[no-any-return]
  File "/home/user/fproject/sport_auth/routes/user_routes.py", line 109, in get_weight_progress
    progress = 100 - (cur_weight_difference / start_weight_difference) * 100
ZeroDivisionError: division by zero
